Workbook

Sheet Start Here
A1: GradPilot · Graduate Applications 2027
A2: A secure, beautifully structured Google Sheets command center for Emmanuel Adoum.
A4: Start in five minutes
A6: 1 | B6: Open Setup | C6: Confirm target intake, timezone, graduation month and score weights. | E6: Keep this Sheet private in Google Drive. Do not store application-portal passwords, payment-card details, TOTP codes, or recovery secrets. Use Drive file links for documents and check sharing before adding collaborators. The Sheet is a planning tracker—not a password manager.
A7: 2 | B7: Replace SAMPLE rows | C7: Every tracker tab contains one blue SAMPLE row. Replace it with your first real record or delete it.
A8: 3 | B8: Use stable IDs | C8: Create short unique IDs such as PRG-001, APP-001 and DOC-001. Linked tabs use these IDs.
A9: 4 | B9: Enter verified deadlines | C9: Add the official source URL and Last Verified date. Never rely only on memory.
A10: 5 | B10: Review Dashboard weekly | C10: The dashboard ignores IDs beginning with SAMPLE- and updates from your real records.
A13: Workbook map
A15: Dashboard | B15: What needs attention now | E15: Input | F15: Pale yellow cells are intended for manual setup values.
A16: Programs | B16: University/program shortlist and weighted fit score | E16: Formula | F16: Pale green cells are calculated—avoid overwriting them.
A17: Scholarships | B17: Funding eligibility, compatibility and deadlines | E17: Sample | F17: Pale blue rows demonstrate entry structure and are ignored by Dashboard.
A18: Applications | B18: Submission pipeline, fees, blockers and decisions | E18: Urgent | F18: Amber/red means due soon, overdue, blocked or needs verification.
A19: Deadlines / Tasks / Reminders | B19: Planning and follow-up system
A20: Documents / Essays | B20: Material readiness and version tracking
A21: Recommenders / Contacts | B21: People, requests and follow-ups
A22: Costs / Decisions | B22: Spending and offer comparison
A23: Setup | B23: Editable defaults, weights and status reference lists

Sheet Dashboard
A1: GradPilot Dashboard
A2: Application cycle 2027 · Africa/Accra · SAMPLE rows are excluded from every metric.
A4: Your application command center
A6: Programs tracked | C6: Active applications | E6: Scholarships tracked | G6: Tasks due in 7 days | I6: Documents ready | K6: Deadlines in 30 days
A7: =COUNTIFS(Programs!$A$6:$A$205,"<>",Programs!$A$6:$A$205,"<>SAMPLE*") -> 12 | C7: =COUNTIFS(Applications!$A$6:$A$205,"<>",Applications!$A$6:$A$205,"<>SAMPLE*",Applications!$E$6:$E$205,"Preparing")+COUNTIFS(Applications!$A$6:$A$205,"<>",Applications!$A$6:$A$205,"<>SAMPLE*",Applications!$E$6:$E$205,"Ready")+COUNTIFS(Applications!$A$6:$A$205,"<>",Applications!$A$6:$A$205,"<>SAMPLE*",Applications!$E$6:$E$205,"Submitted") -> 0 | E7: =COUNTIFS(Scholarships!$A$6:$A$205,"<>",Scholarships!$A$6:$A$205,"<>SAMPLE*") -> 13 | G7: =COUNTIFS(Tasks!$A$6:$A$205,"<>",Tasks!$A$6:$A$205,"<>SAMPLE*",Tasks!$G$6:$G$205,"<>Done",Tasks!$F$6:$F$205,">="&TODAY(),Tasks!$F$6:$F$205,"<="&TODAY()+7) -> 0 | I7: =COUNTIFS(Documents!$A$6:$A$205,"<>",Documents!$A$6:$A$205,"<>SAMPLE*",Documents!$G$6:$G$205,"Ready") -> 0 | K7: =COUNTIFS(Deadlines!$A$6:$A$205,"<>",Deadlines!$A$6:$A$205,"<>SAMPLE*",Deadlines!$H$6:$H$205,"<>Completed",Deadlines!$G$6:$G$205,">="&TODAY(),Deadlines!$G$6:$G$205,"<="&TODAY()+30) -> 0
A12: Next verified deadline | H12: Application pipeline
A13: Deadline | C13: Date | E13: Days left | H13: Researching | I13: =COUNTIFS(Applications!$A$6:$A$205,"<>SAMPLE*",Applications!$A$6:$A$205,"<>",Applications!$E$6:$E$205,H13) -> 0 | K13: Use Applications to move each target through Researching → Preparing → Submitted → Decision. The dashboard updates automatically and excludes SAMPLE rows.
A14: {=IF(C14="","No upcoming real deadline",IFERROR(INDEX(Deadlines!$C$6:$C$205,MATCH(C14,Deadlines!$G$6:$G$205,0)),"Review Deadlines"))} -> No upcoming real deadline | C14: =IF(COUNTIFS(Deadlines!$A$6:$A$205,"<>SAMPLE*",Deadlines!$A$6:$A$205,"<>",Deadlines!$H$6:$H$205,"<>Completed",Deadlines!$G$6:$G$205,">="&TODAY())=0,"",MINIFS(Deadlines!$G$6:$G$205,Deadlines!$A$6:$A$205,"<>SAMPLE*",Deadlines!$H$6:$H$205,"<>Completed",Deadlines!$G$6:$G$205,">="&TODAY())) | E14: =IF(C14="","—",C14-TODAY()) -> — | H14: Shortlisted | I14: =COUNTIFS(Applications!$A$6:$A$205,"<>SAMPLE*",Applications!$A$6:$A$205,"<>",Applications!$E$6:$E$205,H14) -> 0
H15: Preparing | I15: =COUNTIFS(Applications!$A$6:$A$205,"<>SAMPLE*",Applications!$A$6:$A$205,"<>",Applications!$E$6:$E$205,H15) -> 0
H16: Ready | I16: =COUNTIFS(Applications!$A$6:$A$205,"<>SAMPLE*",Applications!$A$6:$A$205,"<>",Applications!$E$6:$E$205,H16) -> 0
H17: Submitted | I17: =COUNTIFS(Applications!$A$6:$A$205,"<>SAMPLE*",Applications!$A$6:$A$205,"<>",Applications!$E$6:$E$205,H17) -> 0
A18: Add the official source URL and Last Verified date in Deadlines before relying on a cutoff. | H18: Decision received | I18: =COUNTIFS(Applications!$A$6:$A$205,"<>SAMPLE*",Applications!$A$6:$A$205,"<>",Applications!$O$6:$O$205,"<>Pending",Applications!$O$6:$O$205,"<>") -> 0
A21: Deadline horizon | H21: Readiness signals
A22: Overdue | B22: =COUNTIFS(Deadlines!$A$6:$A$205,"<>SAMPLE*",Deadlines!$A$6:$A$205,"<>",Deadlines!$H$6:$H$205,"<>Completed",Deadlines!$G$6:$G$205,"<"&TODAY()) -> 0 | H22: Open blocking tasks | I22: =COUNTIFS(Tasks!$A$6:$A$205,"<>SAMPLE*",Tasks!$A$6:$A$205,"<>",Tasks!$H$6:$H$205,TRUE,Tasks!$G$6:$G$205,"<>Done") -> 0 | K22: Weekly rhythm 1. Verify external deadlines. 2. Clear blockers. 3. Update document versions. 4. Follow up with recommenders. 5. Review scholarships and costs.
A23: Today | B23: =COUNTIFS(Deadlines!$A$6:$A$205,"<>SAMPLE*",Deadlines!$A$6:$A$205,"<>",Deadlines!$H$6:$H$205,"<>Completed",Deadlines!$G$6:$G$205,TODAY()) -> 0 | H23: Documents ready | I23: =COUNTIFS(Documents!$A$6:$A$205,"<>SAMPLE*",Documents!$A$6:$A$205,"<>",Documents!$G$6:$G$205,"Ready") -> 0
A24: Next 7 days | B24: =COUNTIFS(Deadlines!$A$6:$A$205,"<>SAMPLE*",Deadlines!$A$6:$A$205,"<>",Deadlines!$H$6:$H$205,"<>Completed",Deadlines!$G$6:$G$205,">"&TODAY(),Deadlines!$G$6:$G$205,"<="&TODAY()+7) -> 0 | H24: Essays final | I24: =COUNTIFS(Essays!$A$6:$A$205,"<>SAMPLE*",Essays!$A$6:$A$205,"<>",Essays!$G$6:$G$205,"Final") -> 0
A25: Next 30 days | B25: =COUNTIFS(Deadlines!$A$6:$A$205,"<>SAMPLE*",Deadlines!$A$6:$A$205,"<>",Deadlines!$H$6:$H$205,"<>Completed",Deadlines!$G$6:$G$205,">"&TODAY()+7,Deadlines!$G$6:$G$205,"<="&TODAY()+30) -> 0 | H25: Recommendations submitted | I25: =COUNTIFS(Recommenders!$A$6:$A$205,"<>SAMPLE*",Recommenders!$A$6:$A$205,"<>",Recommenders!$H$6:$H$205,"Submitted") -> 0
H26: Costs currently due | I26: =COUNTIFS(Costs!$A$6:$A$205,"<>SAMPLE*",Costs!$A$6:$A$205,"<>",Costs!$H$6:$H$205,"Due") -> 0
A29: Start by replacing the SAMPLE rows in Programs, Applications and Deadlines. Your real metrics will appear here automatically.
A31: Financial overview · one plan, three currencies
A33: Total costs · GHS | E33: Total costs · EUR | I33: Total costs · USD
A34: =SUMIFS(Costs!$L$6:$L$205,Costs!$A$6:$A$205,"<>SAMPLE*",Costs!$A$6:$A$205,"<>",Costs!$H$6:$H$205,"<>Waived",Costs!$H$6:$H$205,"<>Refunded") -> 0 | E34: =SUMIFS(Costs!$M$6:$M$205,Costs!$A$6:$A$205,"<>SAMPLE*",Costs!$A$6:$A$205,"<>",Costs!$H$6:$H$205,"<>Waived",Costs!$H$6:$H$205,"<>Refunded") -> 0 | I34: =SUMIFS(Costs!$N$6:$N$205,Costs!$A$6:$A$205,"<>SAMPLE*",Costs!$A$6:$A$205,"<>",Costs!$H$6:$H$205,"<>Waived",Costs!$H$6:$H$205,"<>Refunded") -> 0
A38: Potential funding · GHS | E38: Potential funding · EUR | I38: Potential funding · USD
A39: =SUMIFS(Scholarships!$S$6:$S$205,Scholarships!$A$6:$A$205,"<>SAMPLE*",Scholarships!$A$6:$A$205,"<>",Scholarships!$L$6:$L$205,"<>Rejected",Scholarships!$L$6:$L$205,"<>Withdrawn",Scholarships!$L$6:$L$205,"<>Not Required") -> 1047949 | E39: =SUMIFS(Scholarships!$T$6:$T$205,Scholarships!$A$6:$A$205,"<>SAMPLE*",Scholarships!$A$6:$A$205,"<>",Scholarships!$L$6:$L$205,"<>Rejected",Scholarships!$L$6:$L$205,"<>Withdrawn",Scholarships!$L$6:$L$205,"<>Not Required") -> 80500 | I39: =SUMIFS(Scholarships!$U$6:$U$205,Scholarships!$A$6:$A$205,"<>SAMPLE*",Scholarships!$A$6:$A$205,"<>",Scholarships!$L$6:$L$205,"<>Rejected",Scholarships!$L$6:$L$205,"<>Withdrawn",Scholarships!$L$6:$L$205,"<>Not Required") -> 94092.449
A43: Confirmed funding · GHS | E43: Confirmed funding · EUR | I43: Confirmed funding · USD
A44: =SUMIFS(Decisions!$N$6:$N$205,Decisions!$A$6:$A$205,"<>SAMPLE*",Decisions!$A$6:$A$205,"<>",Decisions!$E$6:$E$205,"Awarded") -> 0 | E44: =SUMIFS(Decisions!$O$6:$O$205,Decisions!$A$6:$A$205,"<>SAMPLE*",Decisions!$A$6:$A$205,"<>",Decisions!$E$6:$E$205,"Awarded") -> 0 | I44: =SUMIFS(Decisions!$P$6:$P$205,Decisions!$A$6:$A$205,"<>SAMPLE*",Decisions!$A$6:$A$205,"<>",Decisions!$E$6:$E$205,"Awarded") -> 0
A48: Confirmed gap · GHS | E48: Confirmed gap · EUR | I48: Confirmed gap · USD
A49: =A34-A44 -> 0 | E49: =E34-E44 -> 0 | I49: =I34-I44 -> 0
A53: Record each expense once in Costs; the Application Fee field is reference-only to prevent double counting. Costs exclude Waived and Refunded items. Potential funding includes active scholarship amounts; confirmed funding includes only awards recorded in Decisions. All conversions use Setup’s effective GHS rate.

Sheet Programs
A1: Programs
A2: Shortlist programs, score fit transparently, and keep official links and verification dates.
A3: Tip: SAMPLE rows are instructional and ignored by Dashboard.
A5: Program ID | B5: Institution | C5: Program | D5: Degree | E5: Country | F5: Intake | G5: Status | H5: Priority | I5: Academic Fit | J5: Research/Career Fit | K5: Funding Strength | L5: Admission Feasibility | M5: Location Fit | N5: Weighted Score | O5: Next Deadline | P5: Official URL | Q5: Application Portal | R5: Last Verified | S5: Notes | T5: Official URL | U5: Application Portal | V5: Last Verified | W5: Notes
A6: PRG-2027-001 | B6: University of Lille | C6: MSc Data Science | D6: MSc | E6: France | F6: Fall 2027 | G6: Shortlisted | H6: 5 | I6: 5 | J6: 5 | K6: 4 | L6: 4 | M6: 5 | N6: =IF(A6="","",IF(COUNT(I6:M6)<5,"",ROUND(SUMPRODUCT(I6:M6,Setup!$A$12:$E$12)/5,0))) -> 92 | O6: =IF(A6="","",IF(COUNTIFS(Deadlines!$D$6:$D$205,A6,Deadlines!$H$6:$H$205,"<>Completed",Deadlines!$G$6:$G$205,"<>")=0,"",MINIFS(Deadlines!$G$6:$G$205,Deadlines!$D$6:$D$205,A6,Deadlines!$H$6:$H$205,"<>Completed"))) | P6: https://sciences-technologies.univ-lille.fr/informatique/formation/master-data-science | R6: 46256 | S6: Strong target. Computer Engineering and EE are explicitly accepted; fully taught in English. The 2027 admission and fellowship deadlines are not yet published.
A7: PRG-2027-002 | B7: University of Passau | C7: MSc Artificial Intelligence Engineering | D7: MSc | E7: Germany | F7: Winter 2027/28 | G7: Shortlisted | H7: 5 | I7: 5 | J7: 5 | K7: 2 | L7: 4 | M7: 4 | N7: =IF(A7="","",IF(COUNT(I7:M7)<5,"",ROUND(SUMPRODUCT(I7:M7,Setup!$A$12:$E$12)/5,0))) -> 80 | O7: =IF(A7="","",IF(COUNTIFS(Deadlines!$D$6:$D$205,A7,Deadlines!$H$6:$H$205,"<>Completed",Deadlines!$G$6:$G$205,"<>")=0,"",MINIFS(Deadlines!$G$6:$G$205,Deadlines!$D$6:$D$205,A7,Deadlines!$H$6:$H$205,"<>Completed"))) | P7: https://www.uni-passau.de/en/msc-ai-eng | R7: 46256 | S7: Strong target if the transcript maps to at least 35 ECTS in mathematics/theoretical CS and 40 ECTS in CS. No tuition; semester fee only.
A8: PRG-2027-003 | B8: Université Côte d’Azur | C8: MSc Data Science and Artificial Intelligence | D8: MSc | E8: France | F8: Fall 2027 | G8: Shortlisted | H8: 5 | I8: 5 | J8: 5 | K8: 4 | L8: 3 | M8: 5 | N8: =IF(A8="","",IF(COUNT(I8:M8)<5,"",ROUND(SUMPRODUCT(I8:M8,Setup!$A$12:$E$12)/5,0))) -> 89 | O8: =IF(A8="","",IF(COUNTIFS(Deadlines!$D$6:$D$205,A8,Deadlines!$H$6:$H$205,"<>Completed",Deadlines!$G$6:$G$205,"<>")=0,"",MINIFS(Deadlines!$G$6:$G$205,Deadlines!$D$6:$D$205,A8,Deadlines!$H$6:$H$205,"<>Completed"))) | P8: https://univ-cotedazur.eu/msc/msc-data-science-and-artificial-intelligence | R8: 46256 | S8: Competitive target combining applied AI and data science. IdEx funding is limited to 10 MSc awardees.
A9: PRG-2027-004 | B9: University of Passau | C9: MSc Computer Science | D9: MSc | E9: Germany | F9: Winter 2027/28 | G9: Shortlisted | H9: 4 | I9: 4 | J9: 5 | K9: 2 | L9: 3 | M9: 4 | N9: =IF(A9="","",IF(COUNT(I9:M9)<5,"",ROUND(SUMPRODUCT(I9:M9,Setup!$A$12:$E$12)/5,0))) -> 73 | O9: =IF(A9="","",IF(COUNTIFS(Deadlines!$D$6:$D$205,A9,Deadlines!$H$6:$H$205,"<>Completed",Deadlines!$G$6:$G$205,"<>")=0,"",MINIFS(Deadlines!$G$6:$G$205,Deadlines!$D$6:$D$205,A9,Deadlines!$H$6:$H$205,"<>Completed"))) | P9: https://www.uni-passau.de/en/msc-computer-science | R9: 46256 | S9: Conditional target: approximately two-thirds of prior credits must be in computer science. No tuition; semester fee only.
A10: PRG-2027-005 | B10: Université Grenoble Alpes / Grenoble INP | C10: MSc Computer Science — MoSIG | D10: MSc | E10: France | F10: Fall 2027 | G10: Shortlisted | H10: 5 | I10: 5 | J10: 5 | K10: 4 | L10: 3 | M10: 5 | N10: =IF(A10="","",IF(COUNT(I10:M10)<5,"",ROUND(SUMPRODUCT(I10:M10,Setup!$A$12:$E$12)/5,0))) -> 89 | O10: =IF(A10="","",IF(COUNTIFS(Deadlines!$D$6:$D$205,A10,Deadlines!$H$6:$H$205,"<>Completed",Deadlines!$G$6:$G$205,"<>")=0,"",MINIFS(Deadlines!$G$6:$G$205,Deadlines!$D$6:$D$205,A10,Deadlines!$H$6:$H$205,"<>Completed"))) | P10: https://mosig.imag.fr/ | R10: 46256 | S10: Target/reach with broad research coverage in AI, software, distributed systems, security and data. Confirm MoSIG’s 2027 IdEx eligibility.
A11: PRG-2027-006 | B11: IMT Atlantique | C11: MSc Information Technology — Embedded AI | D11: MSc | E11: France | F11: Fall 2027 | G11: Shortlisted | H11: 4 | I11: 5 | J11: 4 | K11: 2 | L11: 3 | M11: 5 | N11: =IF(A11="","",IF(COUNT(I11:M11)<5,"",ROUND(SUMPRODUCT(I11:M11,Setup!$A$12:$E$12)/5,0))) -> 73 | O11: =IF(A11="","",IF(COUNTIFS(Deadlines!$D$6:$D$205,A11,Deadlines!$H$6:$H$205,"<>Completed",Deadlines!$G$6:$G$205,"<>")=0,"",MINIFS(Deadlines!$G$6:$G$205,Deadlines!$D$6:$D$205,A11,Deadlines!$H$6:$H$205,"<>Completed"))) | P11: https://www.imt-atlantique.fr/en/study/masters/msc/it-embedded-ai | R11: 46256 | S11: Hybrid target and the strongest software-plus-embedded option. Merit support is a partial tuition waiver and the amount varies.
A12: PRG-2027-007 | B12: TU Darmstadt | C12: MSc Artificial Intelligence and Machine Learning | D12: MSc | E12: Germany | F12: Winter 2027/28 | G12: Shortlisted | H12: 4 | I12: 4 | J12: 5 | K12: 2 | L12: 2 | M12: 4 | N12: =IF(A12="","",IF(COUNT(I12:M12)<5,"",ROUND(SUMPRODUCT(I12:M12,Setup!$A$12:$E$12)/5,0))) -> 70 | O12: =IF(A12="","",IF(COUNTIFS(Deadlines!$D$6:$D$205,A12,Deadlines!$H$6:$H$205,"<>Completed",Deadlines!$G$6:$G$205,"<>")=0,"",MINIFS(Deadlines!$G$6:$G$205,Deadlines!$D$6:$D$205,A12,Deadlines!$H$6:$H$205,"<>Completed"))) | P12: https://www.tu-darmstadt.de/studieren/studieninteressierte/studienangebot_studiengaenge/studiengang_334592.en.jsp | R12: 46256 | S12: Competitive. If prerequisite competencies cannot be verified from the file, a 90-minute entrance examination may be required on campus.
A13: PRG-2027-008 | B13: Paderborn University | C13: MSc Computer Science | D13: MSc | E13: Germany | F13: Winter 2027/28 | G13: Shortlisted | H13: 3 | I13: 4 | J13: 4 | K13: 2 | L13: 3 | M13: 4 | N13: =IF(A13="","",IF(COUNT(I13:M13)<5,"",ROUND(SUMPRODUCT(I13:M13,Setup!$A$12:$E$12)/5,0))) -> 67 | O13: =IF(A13="","",IF(COUNTIFS(Deadlines!$D$6:$D$205,A13,Deadlines!$H$6:$H$205,"<>Completed",Deadlines!$G$6:$G$205,"<>")=0,"",MINIFS(Deadlines!$G$6:$G$205,Deadlines!$D$6:$D$205,A13,Deadlines!$H$6:$H$205,"<>Completed"))) | P13: https://www.uni-paderborn.de/en/studyoffer/course_of_study/computer-science-master | R13: 46256 | S13: Conditional target because degree equivalence is reviewed strictly. No tuition; semester contribution applies.
A14: PRG-2027-009 | B14: Université Paris-Saclay | C14: M1 Artificial Intelligence | D14: MSc | E14: France | F14: Fall 2027 | G14: Shortlisted | H14: 5 | I14: 5 | J14: 5 | K14: 5 | L14: 2 | M14: 5 | N14: =IF(A14="","",IF(COUNT(I14:M14)<5,"",ROUND(SUMPRODUCT(I14:M14,Setup!$A$12:$E$12)/5,0))) -> 91 | O14: =IF(A14="","",IF(COUNTIFS(Deadlines!$D$6:$D$205,A14,Deadlines!$H$6:$H$205,"<>Completed",Deadlines!$G$6:$G$205,"<>")=0,"",MINIFS(Deadlines!$G$6:$G$205,Deadlines!$D$6:$D$205,A14,Deadlines!$H$6:$H$205,"<>Completed"))) | P14: https://www.universite-paris-saclay.fr/en/education/masters-degree/computer-science/m1-artificial-intelligence | R14: 46256 | S14: Scholarship reach. IDEX and Eiffel cannot be combined, and only one Paris-Saclay programme may be submitted for Eiffel.
A15: PRG-2027-010 | B15: Saarland University | C15: MSc Data Science and Artificial Intelligence | D15: MSc | E15: Germany | F15: Winter 2027/28 | G15: Shortlisted | H15: 4 | I15: 5 | J15: 5 | K15: 2 | L15: 2 | M15: 4 | N15: =IF(A15="","",IF(COUNT(I15:M15)<5,"",ROUND(SUMPRODUCT(I15:M15,Setup!$A$12:$E$12)/5,0))) -> 74 | O15: =IF(A15="","",IF(COUNTIFS(Deadlines!$D$6:$D$205,A15,Deadlines!$H$6:$H$205,"<>Completed",Deadlines!$G$6:$G$205,"<>")=0,"",MINIFS(Deadlines!$G$6:$G$205,Deadlines!$D$6:$D$205,A15,Deadlines!$H$6:$H$205,"<>Completed"))) | P15: https://www.uni-saarland.de/en/study/programmes/master/data-science.html | R15: 46256 | S15: Reach programme with a research-intensive AI and data-science environment at Saarland Informatics Campus.
A16: PRG-2027-011 | B16: RWTH Aachen University | C16: MSc Software Systems Engineering | D16: MSc | E16: Germany | F16: Winter 2027/28 | G16: Shortlisted | H16: 3 | I16: 4 | J16: 5 | K16: 2 | L16: 2 | M16: 4 | N16: =IF(A16="","",IF(COUNT(I16:M16)<5,"",ROUND(SUMPRODUCT(I16:M16,Setup!$A$12:$E$12)/5,0))) -> 70 | O16: =IF(A16="","",IF(COUNTIFS(Deadlines!$D$6:$D$205,A16,Deadlines!$H$6:$H$205,"<>Completed",Deadlines!$G$6:$G$205,"<>")=0,"",MINIFS(Deadlines!$G$6:$G$205,Deadlines!$D$6:$D$205,A16,Deadlines!$H$6:$H$205,"<>Completed"))) | P16: https://www.rwth-aachen.de/cms/root/studium/vor-dem-studium/studiengaenge/liste-aktuelle-studiengaenge/studiengangbeschreibung/~bnhr/software-systems-engineering-m-sc/?lidx=1 | R16: 46256 | S16: Reach programme focused on large software systems. Exact consecutive-CS prerequisites should be audited against the transcript.
A17: PRG-2027-012 | B17: ENS de Lyon | C17: Master of Computer Science — Concepts and Applications | D17: MSc | E17: France | F17: Fall 2027 | G17: Shortlisted | H17: 3 | I17: 5 | J17: 5 | K17: 4 | L17: 1 | M17: 5 | N17: =IF(A17="","",IF(COUNT(I17:M17)<5,"",ROUND(SUMPRODUCT(I17:M17,Setup!$A$12:$E$12)/5,0))) -> 83 | O17: =IF(A17="","",IF(COUNTIFS(Deadlines!$D$6:$D$205,A17,Deadlines!$H$6:$H$205,"<>Completed",Deadlines!$G$6:$G$205,"<>")=0,"",MINIFS(Deadlines!$G$6:$G$205,Deadlines!$D$6:$D$205,A17,Deadlines!$H$6:$H$205,"<>Completed"))) | P17: https://informatique.ens-lyon.fr/en/academic-programs/computer-science-department | R17: 46256 | S17: High reach. Research-oriented computer science taught in English; admission and the Ampère scholarship are highly selective.
N18: =IF(A18="","",IF(COUNT(I18:M18)<5,"",ROUND(SUMPRODUCT(I18:M18,Setup!$A$12:$E$12)/5,0))) | O18: =IF(A18="","",IF(COUNTIFS(Deadlines!$D$6:$D$205,A18,Deadlines!$H$6:$H$205,"<>Completed",Deadlines!$G$6:$G$205,"<>")=0,"",MINIFS(Deadlines!$G$6:$G$205,Deadlines!$D$6:$D$205,A18,Deadlines!$H$6:$H$205,"<>Completed")))
N19: =IF(A19="","",IF(COUNT(I19:M19)<5,"",ROUND(SUMPRODUCT(I19:M19,Setup!$A$12:$E$12)/5,0))) | O19: =IF(A19="","",IF(COUNTIFS(Deadlines!$D$6:$D$205,A19,Deadlines!$H$6:$H$205,"<>Completed",Deadlines!$G$6:$G$205,"<>")=0,"",MINIFS(Deadlines!$G$6:$G$205,Deadlines!$D$6:$D$205,A19,Deadlines!$H$6:$H$205,"<>Completed")))
N20: =IF(A20="","",IF(COUNT(I20:M20)<5,"",ROUND(SUMPRODUCT(I20:M20,Setup!$A$12:$E$12)/5,0))) | O20: =IF(A20="","",IF(COUNTIFS(Deadlines!$D$6:$D$205,A20,Deadlines!$H$6:$H$205,"<>Completed",Deadlines!$G$6:$G$205,"<>")=0,"",MINIFS(Deadlines!$G$6:$G$205,Deadlines!$D$6:$D$205,A20,Deadlines!$H$6:$H$205,"<>Completed")))
N21: =IF(A21="","",IF(COUNT(I21:M21)<5,"",ROUND(SUMPRODUCT(I21:M21,Setup!$A$12:$E$12)/5,0))) | O21: =IF(A21="","",IF(COUNTIFS(Deadlines!$D$6:$D$205,A21,Deadlines!$H$6:$H$205,"<>Completed",Deadlines!$G$6:$G$205,"<>")=0,"",MINIFS(Deadlines!$G$6:$G$205,Deadlines!$D$6:$D$205,A21,Deadlines!$H$6:$H$205,"<>Completed")))
N22: =IF(A22="","",IF(COUNT(I22:M22)<5,"",ROUND(SUMPRODUCT(I22:M22,Setup!$A$12:$E$12)/5,0))) | O22: =IF(A22="","",IF(COUNTIFS(Deadlines!$D$6:$D$205,A22,Deadlines!$H$6:$H$205,"<>Completed",Deadlines!$G$6:$G$205,"<>")=0,"",MINIFS(Deadlines!$G$6:$G$205,Deadlines!$D$6:$D$205,A22,Deadlines!$H$6:$H$205,"<>Completed")))
N23: =IF(A23="","",IF(COUNT(I23:M23)<5,"",ROUND(SUMPRODUCT(I23:M23,Setup!$A$12:$E$12)/5,0))) | O23: =IF(A23="","",IF(COUNTIFS(Deadlines!$D$6:$D$205,A23,Deadlines!$H$6:$H$205,"<>Completed",Deadlines!$G$6:$G$205,"<>")=0,"",MINIFS(Deadlines!$G$6:$G$205,Deadlines!$D$6:$D$205,A23,Deadlines!$H$6:$H$205,"<>Completed")))
N24: =IF(A24="","",IF(COUNT(I24:M24)<5,"",ROUND(SUMPRODUCT(I24:M24,Setup!$A$12:$E$12)/5,0))) | O24: =IF(A24="","",IF(COUNTIFS(Deadlines!$D$6:$D$205,A24,Deadlines!$H$6:$H$205,"<>Completed",Deadlines!$G$6:$G$205,"<>")=0,"",MINIFS(Deadlines!$G$6:$G$205,Deadlines!$D$6:$D$205,A24,Deadlines!$H$6:$H$205,"<>Completed")))
N25: =IF(A25="","",IF(COUNT(I25:M25)<5,"",ROUND(SUMPRODUCT(I25:M25,Setup!$A$12:$E$12)/5,0))) | O25: =IF(A25="","",IF(COUNTIFS(Deadlines!$D$6:$D$205,A25,Deadlines!$H$6:$H$205,"<>Completed",Deadlines!$G$6:$G$205,"<>")=0,"",MINIFS(Deadlines!$G$6:$G$205,Deadlines!$D$6:$D$205,A25,Deadlines!$H$6:$H$205,"<>Completed")))
N26: =IF(A26="","",IF(COUNT(I26:M26)<5,"",ROUND(SUMPRODUCT(I26:M26,Setup!$A$12:$E$12)/5,0))) | O26: =IF(A26="","",IF(COUNTIFS(Deadlines!$D$6:$D$205,A26,Deadlines!$H$6:$H$205,"<>Completed",Deadlines!$G$6:$G$205,"<>")=0,"",MINIFS(Deadlines!$G$6:$G$205,Deadlines!$D$6:$D$205,A26,Deadlines!$H$6:$H$205,"<>Completed")))
N27: =IF(A27="","",IF(COUNT(I27:M27)<5,"",ROUND(SUMPRODUCT(I27:M27,Setup!$A$12:$E$12)/5,0))) | O27: =IF(A27="","",IF(COUNTIFS(Deadlines!$D$6:$D$205,A27,Deadlines!$H$6:$H$205,"<>Completed",Deadlines!$G$6:$G$205,"<>")=0,"",MINIFS(Deadlines!$G$6:$G$205,Deadlines!$D$6:$D$205,A27,Deadlines!$H$6:$H$205,"<>Completed")))
N28: =IF(A28="","",IF(COUNT(I28:M28)<5,"",ROUND(SUMPRODUCT(I28:M28,Setup!$A$12:$E$12)/5,0))) | O28: =IF(A28="","",IF(COUNTIFS(Deadlines!$D$6:$D$205,A28,Deadlines!$H$6:$H$205,"<>Completed",Deadlines!$G$6:$G$205,"<>")=0,"",MINIFS(Deadlines!$G$6:$G$205,Deadlines!$D$6:$D$205,A28,Deadlines!$H$6:$H$205,"<>Completed")))
N29: =IF(A29="","",IF(COUNT(I29:M29)<5,"",ROUND(SUMPRODUCT(I29:M29,Setup!$A$12:$E$12)/5,0))) | O29: =IF(A29="","",IF(COUNTIFS(Deadlines!$D$6:$D$205,A29,Deadlines!$H$6:$H$205,"<>Completed",Deadlines!$G$6:$G$205,"<>")=0,"",MINIFS(Deadlines!$G$6:$G$205,Deadlines!$D$6:$D$205,A29,Deadlines!$H$6:$H$205,"<>Completed")))
... N205: =IF(A205="","",IF(COUNT(I205:M205)<5,"",ROUND(SUMPRODUCT(I205:M205,Setup!$A$12:$E$12)/5,0))) | O205: =IF(A205="","",IF(COUNTIFS(Deadlines!$D$6:$D$205,A205,Deadlines!$H$6:$H$205,"<>Completed",Deadlines!$G$6:$G$205,"<>")=0,"",MINIFS(Deadlines!$G$6:$G$205,Deadlines!$D$6:$D$205,A205,Deadlines!$H$6:$H$205,"<>Completed")))

Sheet Scholarships
A1: Scholarships
A2: Track eligibility, funding coverage, nomination/separate applications, and verified deadlines.
A3: Tip: SAMPLE rows are instructional and ignored by Dashboard.
A5: Scholarship ID | B5: Scholarship | C5: Provider | D5: Country/Coverage | E5: Program ID | F5: Funding Type | G5: Amount | H5: Currency | I5: Coverage Notes | J5: Mechanism | K5: Eligibility | L5: Status | M5: Priority | N5: Deadline | O5: Days Left | P5: Official URL | Q5: Last Verified | R5: Notes | S5: Amount (GHS) | T5: Amount (EUR) | U5: Amount (USD) | V5: Notes
A6: SCH-2027-001 | B6: University of Lille Graduate Programme Fellowship | C6: University of Lille | D6: France | E6: PRG-2027-001 | F6: Fellowship | G6: 8500 | H6: EUR | I6: €8,500 for one academic year, paid in 10 monthly instalments; renewal may be requested for M2. | J6: Direct Application | K6: Likely | L6: Researching | M6: 5 | O6: =IF(N6="","",N6-TODAY()) | P6: https://graduate-programmes.univ-lille.fr/en/fellowships | Q6: 46256 | R6: 2027 call dates are not yet published. Incoming international students entering a covered Graduate Programme are eligible. | S6: =IF(OR(G6="",H6=""),"",IFERROR(G6*VLOOKUP(H6,Setup!$A$38:$E$52,5,FALSE),"")) -> 110653 | T6: =IF(S6="","",IFERROR(S6/VLOOKUP("EUR",Setup!$A$38:$E$52,5,FALSE),"")) -> 8500 | U6: =IF(S6="","",IFERROR(S6/VLOOKUP("USD",Setup!$A$38:$E$52,5,FALSE),"")) -> 9935.2275
A7: SCH-2027-002 | B7: Deutschlandstipendium — University of Passau | C7: Federal Government + University of Passau | D7: Germany | E7: PRG-2027-002 | F7: Stipend Only | G7: 3600 | H7: EUR | I7: €300 per month for 12 months; international master’s students may apply. Programme tuition is already €0. | J7: Separate | K7: Likely | L7: Researching | M7: 3 | O7: =IF(N7="","",N7-TODAY()) | P7: https://www.uni-passau.de/en/deutschlandstipendium-scholarship/how-to-apply | Q7: 46256 | R7: The university states that the next application period will open in May 2027; the closing date is not yet published. | S7: =IF(OR(G7="",H7=""),"",IFERROR(G7*VLOOKUP(H7,Setup!$A$38:$E$52,5,FALSE),"")) -> 46864.8 | T7: =IF(S7="","",IFERROR(S7/VLOOKUP("EUR",Setup!$A$38:$E$52,5,FALSE),"")) -> 3600 | U7: =IF(S7="","",IFERROR(S7/VLOOKUP("USD",Setup!$A$38:$E$52,5,FALSE),"")) -> 4207.8611
A8: SCH-2027-003 | B8: IdEx Excellence Scholarship — Université Côte d’Azur | C8: Université Côte d’Azur | D8: France | E8: PRG-2027-003 | F8: Tuition + Stipend | G8: 5000 | H8: EUR | I8: Full tuition exemption plus a €5,000 stipend for one year; 10 international MSc awards. | J8: Direct Application | K8: Likely | L8: Researching | M8: 5 | O8: =IF(N8="","",N8-TODAY()) | P8: https://univ-cotedazur.eu/msc-programs/tuition-fees/are-you-an-international-student/academic-excellence-scholarships | Q8: 46256 | R8: The latest official award structure is recorded; the 2027 deadline is not yet published. | S8: =IF(OR(G8="",H8=""),"",IFERROR(G8*VLOOKUP(H8,Setup!$A$38:$E$52,5,FALSE),"")) -> 65090 | T8: =IF(S8="","",IFERROR(S8/VLOOKUP("EUR",Setup!$A$38:$E$52,5,FALSE),"")) -> 5000 | U8: =IF(S8="","",IFERROR(S8/VLOOKUP("USD",Setup!$A$38:$E$52,5,FALSE),"")) -> 5844.2515
A9: SCH-2027-004 | B9: Deutschlandstipendium — University of Passau | C9: Federal Government + University of Passau | D9: Germany | E9: PRG-2027-004 | F9: Stipend Only | G9: 3600 | H9: EUR | I9: €300 per month for 12 months; international master’s students may apply. Programme tuition is already €0. | J9: University Application | K9: Likely | L9: Researching | M9: 3 | O9: =IF(N9="","",N9-TODAY()) | P9: https://www.uni-passau.de/en/deutschlandstipendium-scholarship/how-to-apply | Q9: 46256 | R9: The university states that the next application period will open in May 2027; the closing date is not yet published. | S9: =IF(OR(G9="",H9=""),"",IFERROR(G9*VLOOKUP(H9,Setup!$A$38:$E$52,5,FALSE),"")) -> 46864.8 | T9: =IF(S9="","",IFERROR(S9/VLOOKUP("EUR",Setup!$A$38:$E$52,5,FALSE),"")) -> 3600 | U9: =IF(S9="","",IFERROR(S9/VLOOKUP("USD",Setup!$A$38:$E$52,5,FALSE),"")) -> 4207.8611
A10: SCH-2027-005 | B10: IdEx Master Scholarship — Grenoble | C10: Université Grenoble Alpes | D10: France | E10: PRG-2027-005 | F10: Stipend Only | G10: 9000 | H10: EUR | I10: €9,000 for M1 for one year. Tuition waiver is not automatic; confirm MoSIG participation in the 2027 call. | J10: Nomination | K10: Unknown | L10: Researching | M10: 5 | O10: =IF(N10="","",N10-TODAY()) | P10: https://www.univ-grenoble-alpes.fr/call-for-applications-idex-master-scholarships-2026-2027-academic-year-1545508.kjsp | Q10: 46256 | R10: Latest official M1 amount recorded. Verify that MoSIG remains eligible when the 2027 call opens. | S10: =IF(OR(G10="",H10=""),"",IFERROR(G10*VLOOKUP(H10,Setup!$A$38:$E$52,5,FALSE),"")) -> 117162 | T10: =IF(S10="","",IFERROR(S10/VLOOKUP("EUR",Setup!$A$38:$E$52,5,FALSE),"")) -> 9000 | U10: =IF(S10="","",IFERROR(S10/VLOOKUP("USD",Setup!$A$38:$E$52,5,FALSE),"")) -> 10519.653
A11: SCH-2027-006 | B11: IMT Atlantique Merit-Based Fellowship | C11: IMT Atlantique | D11: France | E11: PRG-2027-006 | F11: Partial Tuition | H11: EUR | I11: Partial tuition-fee waiver for strong MSc applicants; no separate scholarship application; award amount varies. | J11: Automatic | K11: Likely | L11: Researching | M11: 4 | O11: =IF(N11="","",N11-TODAY()) | P11: https://www.imt-atlantique.fr/en/international/study-imt-atlantique/practical-information/scholarships-fundings | Q11: 46256 | R11: All MSc applications are considered automatically; the official page does not publish a fixed waiver amount. | S11: =IF(OR(G11="",H11=""),"",IFERROR(G11*VLOOKUP(H11,Setup!$A$38:$E$52,5,FALSE),"")) | T11: =IF(S11="","",IFERROR(S11/VLOOKUP("EUR",Setup!$A$38:$E$52,5,FALSE),"")) | U11: =IF(S11="","",IFERROR(S11/VLOOKUP("USD",Setup!$A$38:$E$52,5,FALSE),""))
A12: SCH-2027-007 | B12: Deutschlandstipendium — TU Darmstadt | C12: Federal Government + TU Darmstadt | D12: Germany | E12: PRG-2027-007 | F12: Stipend Only | G12: 3600 | H12: EUR | I12: €300 per month for one year; open to students and incoming first-semester students selected on merit and engagement. | J12: University Application | K12: Likely | L12: Researching | M12: 3 | O12: =IF(N12="","",N12-TODAY()) | P12: https://www.tu-darmstadt.de/deutschlandstipendium/index.en.jsp | Q12: 46256 | R12: The 2027 application dates are not yet published. This is supplementary funding, not full living-cost coverage. | S12: =IF(OR(G12="",H12=""),"",IFERROR(G12*VLOOKUP(H12,Setup!$A$38:$E$52,5,FALSE),"")) -> 46864.8 | T12: =IF(S12="","",IFERROR(S12/VLOOKUP("EUR",Setup!$A$38:$E$52,5,FALSE),"")) -> 3600 | U12: =IF(S12="","",IFERROR(S12/VLOOKUP("USD",Setup!$A$38:$E$52,5,FALSE),"")) -> 4207.8611
A13: SCH-2027-008 | B13: Deutschlandstipendium — Paderborn University | C13: Federal Government + Studienfonds OWL | D13: Germany | E13: PRG-2027-008 | F13: Stipend Only | G13: 3600 | H13: EUR | I13: €300 per month for 12 months; selection considers academic performance and engagement. | J13: University Application | K13: Likely | L13: Researching | M13: 3 | O13: =IF(N13="","",N13-TODAY()) | P13: https://www2.daad.de/deutschland/stipendium/datenbank/en/21148-scholarship-database/?detail=10000207 | Q13: 46256 | R13: Confirm Paderborn’s 2027 institutional application window after admission. | S13: =IF(OR(G13="",H13=""),"",IFERROR(G13*VLOOKUP(H13,Setup!$A$38:$E$52,5,FALSE),"")) -> 46864.8 | T13: =IF(S13="","",IFERROR(S13/VLOOKUP("EUR",Setup!$A$38:$E$52,5,FALSE),"")) -> 3600 | U13: =IF(S13="","",IFERROR(S13/VLOOKUP("USD",Setup!$A$38:$E$52,5,FALSE),"")) -> 4207.8611
A14: SCH-2027-009 | B14: Paris-Saclay International Master’s Scholarship (IDEX) | C14: Université Paris-Saclay | D14: France | E14: PRG-2027-009 | F14: Fellowship | G14: 10000 | H14: EUR | I14: €10,000 per academic year plus up to €900 for travel and visa; renewable from M1 to M2; cannot be combined with Eiffel. | J14: Nomination | K14: Likely | L14: Researching | M14: 5 | O14: =IF(N14="","",N14-TODAY()) | P14: https://www.universite-paris-saclay.fr/en/admission/bourses-et-aides-financieres/international-masters-scholarships-program | Q14: 46256 | R14: Selection is by programme coordinators after admission; there is no ordinary self-nomination route. | S14: =IF(OR(G14="",H14=""),"",IFERROR(G14*VLOOKUP(H14,Setup!$A$38:$E$52,5,FALSE),"")) -> 130180 | T14: =IF(S14="","",IFERROR(S14/VLOOKUP("EUR",Setup!$A$38:$E$52,5,FALSE),"")) -> 10000 | U14: =IF(S14="","",IFERROR(S14/VLOOKUP("USD",Setup!$A$38:$E$52,5,FALSE),"")) -> 11688.503
A15: SCH-2027-010 | B15: France Excellence Eiffel Scholarship — Paris-Saclay | C15: French Ministry for Europe and Foreign Affairs / Campus France | D15: France | E15: PRG-2027-009 | F15: Government Sponsorship | G15: 14400 | H15: EUR | I15: €1,200 per month, annualised here as €14,400, plus direct services; up to 24 months for M1; cannot be combined with IDEX. | J15: Nomination | K15: Likely | L15: Researching | M15: 5 | O15: =IF(N15="","",N15-TODAY()) | P15: https://www.universite-paris-saclay.fr/en/admission/bourses-et-aides-financieres/france-excellence-eiffel-scholarship | Q15: 46256 | R15: The 2027 Paris-Saclay institutional deadline is not yet published. Only one institution and one Paris-Saclay programme may nominate the candidate. | S15: =IF(OR(G15="",H15=""),"",IFERROR(G15*VLOOKUP(H15,Setup!$A$38:$E$52,5,FALSE),"")) -> 187459.2 | T15: =IF(S15="","",IFERROR(S15/VLOOKUP("EUR",Setup!$A$38:$E$52,5,FALSE),"")) -> 14400 | U15: =IF(S15="","",IFERROR(S15/VLOOKUP("USD",Setup!$A$38:$E$52,5,FALSE),"")) -> 16831.444
A16: SCH-2027-011 | B16: Deutschlandstipendium — Saarland University | C16: Federal Government + Saarland University | D16: Germany | E16: PRG-2027-010 | F16: Stipend Only | G16: 3600 | H16: EUR | I16: €300 per month for one year, regardless of nationality; applications are normally accepted in June. | J16: University Application | K16: Likely | L16: Researching | M16: 3 | O16: =IF(N16="","",N16-TODAY()) | P16: https://www.uni-saarland.de/en/global/welcome-center/preparing/financing.html | Q16: 46256 | R16: The university states applications are possible from 1–30 June each year; reconfirm the 2027 cycle before entry. | S16: =IF(OR(G16="",H16=""),"",IFERROR(G16*VLOOKUP(H16,Setup!$A$38:$E$52,5,FALSE),"")) -> 46864.8 | T16: =IF(S16="","",IFERROR(S16/VLOOKUP("EUR",Setup!$A$38:$E$52,5,FALSE),"")) -> 3600 | U16: =IF(S16="","",IFERROR(S16/VLOOKUP("USD",Setup!$A$38:$E$52,5,FALSE),"")) -> 4207.8611
A17: SCH-2027-012 | B17: Deutschlandstipendium — RWTH Aachen | C17: Federal Government + RWTH Aachen | D17: Germany | E17: PRG-2027-011 | F17: Stipend Only | G17: 3600 | H17: EUR | I17: €300 per month; selection considers academic achievement and broader personal or social engagement. | J17: Separate | K17: Likely | L17: Researching | M17: 3 | O17: =IF(N17="","",N17-TODAY()) | P17: https://www.rwth-aachen.de/cms/root/transfer/spenden-und-sponsoring/deutschlandstipendium/~emd/bewerben/?lidx=1 | Q17: 46256 | R17: The 2027 application window is not yet published; scholarship funding is supplementary. | S17: =IF(OR(G17="",H17=""),"",IFERROR(G17*VLOOKUP(H17,Setup!$A$38:$E$52,5,FALSE),"")) -> 46864.8 | T17: =IF(S17="","",IFERROR(S17/VLOOKUP("EUR",Setup!$A$38:$E$52,5,FALSE),"")) -> 3600 | U17: =IF(S17="","",IFERROR(S17/VLOOKUP("USD",Setup!$A$38:$E$52,5,FALSE),"")) -> 4207.8611
A18: SCH-2027-013 | B18: Ampère Scholarship of Excellence | C18: ENS de Lyon | D18: France | E18: PRG-2027-012 | F18: Fellowship | G18: 12000 | H18: EUR | I18: €1,000 per month for 12 months; award is highly competitive and renewal is subject to the applicable call conditions. | J18: Direct Application | K18: Likely | L18: Researching | M18: 5 | O18: =IF(N18="","",N18-TODAY()) | P18: https://www.ens-lyon.fr/en/studies/admissions/application-masters-degrees-and-scholarships | Q18: 46256 | R18: The latest official value is recorded; exact 2027 application dates are not yet published. | S18: =IF(OR(G18="",H18=""),"",IFERROR(G18*VLOOKUP(H18,Setup!$A$38:$E$52,5,FALSE),"")) -> 156216 | T18: =IF(S18="","",IFERROR(S18/VLOOKUP("EUR",Setup!$A$38:$E$52,5,FALSE),"")) -> 12000 | U18: =IF(S18="","",IFERROR(S18/VLOOKUP("USD",Setup!$A$38:$E$52,5,FALSE),"")) -> 14026.204
O19: =IF(N19="","",N19-TODAY()) | S19: =IF(OR(G19="",H19=""),"",IFERROR(G19*VLOOKUP(H19,Setup!$A$38:$E$52,5,FALSE),"")) | T19: =IF(S19="","",IFERROR(S19/VLOOKUP("EUR",Setup!$A$38:$E$52,5,FALSE),"")) | U19: =IF(S19="","",IFERROR(S19/VLOOKUP("USD",Setup!$A$38:$E$52,5,FALSE),""))
O20: =IF(N20="","",N20-TODAY()) | S20: =IF(OR(G20="",H20=""),"",IFERROR(G20*VLOOKUP(H20,Setup!$A$38:$E$52,5,FALSE),"")) | T20: =IF(S20="","",IFERROR(S20/VLOOKUP("EUR",Setup!$A$38:$E$52,5,FALSE),"")) | U20: =IF(S20="","",IFERROR(S20/VLOOKUP("USD",Setup!$A$38:$E$52,5,FALSE),""))
O21: =IF(N21="","",N21-TODAY()) | S21: =IF(OR(G21="",H21=""),"",IFERROR(G21*VLOOKUP(H21,Setup!$A$38:$E$52,5,FALSE),"")) | T21: =IF(S21="","",IFERROR(S21/VLOOKUP("EUR",Setup!$A$38:$E$52,5,FALSE),"")) | U21: =IF(S21="","",IFERROR(S21/VLOOKUP("USD",Setup!$A$38:$E$52,5,FALSE),""))
O22: =IF(N22="","",N22-TODAY()) | S22: =IF(OR(G22="",H22=""),"",IFERROR(G22*VLOOKUP(H22,Setup!$A$38:$E$52,5,FALSE),"")) | T22: =IF(S22="","",IFERROR(S22/VLOOKUP("EUR",Setup!$A$38:$E$52,5,FALSE),"")) | U22: =IF(S22="","",IFERROR(S22/VLOOKUP("USD",Setup!$A$38:$E$52,5,FALSE),""))
O23: =IF(N23="","",N23-TODAY()) | S23: =IF(OR(G23="",H23=""),"",IFERROR(G23*VLOOKUP(H23,Setup!$A$38:$E$52,5,FALSE),"")) | T23: =IF(S23="","",IFERROR(S23/VLOOKUP("EUR",Setup!$A$38:$E$52,5,FALSE),"")) | U23: =IF(S23="","",IFERROR(S23/VLOOKUP("USD",Setup!$A$38:$E$52,5,FALSE),""))
O24: =IF(N24="","",N24-TODAY()) | S24: =IF(OR(G24="",H24=""),"",IFERROR(G24*VLOOKUP(H24,Setup!$A$38:$E$52,5,FALSE),"")) | T24: =IF(S24="","",IFERROR(S24/VLOOKUP("EUR",Setup!$A$38:$E$52,5,FALSE),"")) | U24: =IF(S24="","",IFERROR(S24/VLOOKUP("USD",Setup!$A$38:$E$52,5,FALSE),""))
O25: =IF(N25="","",N25-TODAY()) | S25: =IF(OR(G25="",H25=""),"",IFERROR(G25*VLOOKUP(H25,Setup!$A$38:$E$52,5,FALSE),"")) | T25: =IF(S25="","",IFERROR(S25/VLOOKUP("EUR",Setup!$A$38:$E$52,5,FALSE),"")) | U25: =IF(S25="","",IFERROR(S25/VLOOKUP("USD",Setup!$A$38:$E$52,5,FALSE),""))
O26: =IF(N26="","",N26-TODAY()) | S26: =IF(OR(G26="",H26=""),"",IFERROR(G26*VLOOKUP(H26,Setup!$A$38:$E$52,5,FALSE),"")) | T26: =IF(S26="","",IFERROR(S26/VLOOKUP("EUR",Setup!$A$38:$E$52,5,FALSE),"")) | U26: =IF(S26="","",IFERROR(S26/VLOOKUP("USD",Setup!$A$38:$E$52,5,FALSE),""))
O27: =IF(N27="","",N27-TODAY()) | S27: =IF(OR(G27="",H27=""),"",IFERROR(G27*VLOOKUP(H27,Setup!$A$38:$E$52,5,FALSE),"")) | T27: =IF(S27="","",IFERROR(S27/VLOOKUP("EUR",Setup!$A$38:$E$52,5,FALSE),"")) | U27: =IF(S27="","",IFERROR(S27/VLOOKUP("USD",Setup!$A$38:$E$52,5,FALSE),""))
O28: =IF(N28="","",N28-TODAY()) | S28: =IF(OR(G28="",H28=""),"",IFERROR(G28*VLOOKUP(H28,Setup!$A$38:$E$52,5,FALSE),"")) | T28: =IF(S28="","",IFERROR(S28/VLOOKUP("EUR",Setup!$A$38:$E$52,5,FALSE),"")) | U28: =IF(S28="","",IFERROR(S28/VLOOKUP("USD",Setup!$A$38:$E$52,5,FALSE),""))
O29: =IF(N29="","",N29-TODAY()) | S29: =IF(OR(G29="",H29=""),"",IFERROR(G29*VLOOKUP(H29,Setup!$A$38:$E$52,5,FALSE),"")) | T29: =IF(S29="","",IFERROR(S29/VLOOKUP("EUR",Setup!$A$38:$E$52,5,FALSE),"")) | U29: =IF(S29="","",IFERROR(S29/VLOOKUP("USD",Setup!$A$38:$E$52,5,FALSE),""))
O30: =IF(N30="","",N30-TODAY()) | S30: =IF(OR(G30="",H30=""),"",IFERROR(G30*VLOOKUP(H30,Setup!$A$38:$E$52,5,FALSE),"")) | T30: =IF(S30="","",IFERROR(S30/VLOOKUP("EUR",Setup!$A$38:$E$52,5,FALSE),"")) | U30: =IF(S30="","",IFERROR(S30/VLOOKUP("USD",Setup!$A$38:$E$52,5,FALSE),""))
... O205: =IF(N205="","",N205-TODAY()) | S205: =IF(OR(G205="",H205=""),"",IFERROR(G205*VLOOKUP(H205,Setup!$A$38:$E$52,5,FALSE),"")) | T205: =IF(S205="","",IFERROR(S205/VLOOKUP("EUR",Setup!$A$38:$E$52,5,FALSE),"")) | U205: =IF(S205="","",IFERROR(S205/VLOOKUP("USD",Setup!$A$38:$E$52,5,FALSE),""))

Sheet Applications
A1: Applications
A2: Track submission readiness, fees, decisions and the next action for every application.
A3: Tip: SAMPLE rows are instructional and ignored by Dashboard.
A5: Application ID | B5: Program ID | C5: Program | D5: Institution | E5: Status | F5: Priority | G5: Round | H5: Program Deadline | I5: Days Left | J5: Open Blockers | K5: Application Fee | L5: Currency | M5: Fee Status | N5: Submitted | O5: Decision | P5: Response Deadline | Q5: Applicant Reference | R5: Portal URL | S5: Notes | T5: Response Deadline | U5: Applicant Reference | V5: Portal URL | W5: Notes
A6: SAMPLE-APP-001 | B6: SAMPLE-PRG-001 | C6: {=IF(B6="","",IFERROR(INDEX(Programs!$C$6:$C$205,MATCH(B6,Programs!$A$6:$A$205,0)),""))} | D6: {=IF(B6="","",IFERROR(INDEX(Programs!$B$6:$B$205,MATCH(B6,Programs!$A$6:$A$205,0)),""))} | E6: Preparing | F6: 5 | G6: Main | H6: =IF(A6="","",IF(COUNTIFS(Deadlines!$D$6:$D$205,A6,Deadlines!$H$6:$H$205,"<>Completed",Deadlines!$G$6:$G$205,"<>")=0,"",MINIFS(Deadlines!$G$6:$G$205,Deadlines!$D$6:$D$205,A6,Deadlines!$H$6:$H$205,"<>Completed"))) -> 46295 | I6: =IF(H6="","",H6-TODAY()) -> 39 | J6: =IF(A6="","",COUNTIFS(Tasks!$D$6:$D$205,A6,Tasks!$G$6:$G$205,"<>Done",Tasks!$H$6:$H$205,TRUE)+COUNTIFS(Documents!$K$6:$K$205,A6,Documents!$G$6:$G$205,"<>Ready")+COUNTIFS(Essays!$C$6:$C$205,A6,Essays!$G$6:$G$205,"<>Final")+COUNTIFS(Recommenders!$G$6:$G$205,A6,Recommenders!$H$6:$H$205,"<>Submitted")) -> 4 | K6: 100 | L6: EUR | M6: Due | O6: Pending | P6: 46371 | S6: Delete or replace this sample row.
C7: {=IF(B7="","",IFERROR(INDEX(Programs!$C$6:$C$205,MATCH(B7,Programs!$A$6:$A$205,0)),""))} | D7: {=IF(B7="","",IFERROR(INDEX(Programs!$B$6:$B$205,MATCH(B7,Programs!$A$6:$A$205,0)),""))} | H7: =IF(A7="","",IF(COUNTIFS(Deadlines!$D$6:$D$205,A7,Deadlines!$H$6:$H$205,"<>Completed",Deadlines!$G$6:$G$205,"<>")=0,"",MINIFS(Deadlines!$G$6:$G$205,Deadlines!$D$6:$D$205,A7,Deadlines!$H$6:$H$205,"<>Completed"))) | I7: =IF(H7="","",H7-TODAY()) | J7: =IF(A7="","",COUNTIFS(Tasks!$D$6:$D$205,A7,Tasks!$G$6:$G$205,"<>Done",Tasks!$H$6:$H$205,TRUE)+COUNTIFS(Documents!$K$6:$K$205,A7,Documents!$G$6:$G$205,"<>Ready")+COUNTIFS(Essays!$C$6:$C$205,A7,Essays!$G$6:$G$205,"<>Final")+COUNTIFS(Recommenders!$G$6:$G$205,A7,Recommenders!$H$6:$H$205,"<>Submitted"))
C8: {=IF(B8="","",IFERROR(INDEX(Programs!$C$6:$C$205,MATCH(B8,Programs!$A$6:$A$205,0)),""))} | D8: {=IF(B8="","",IFERROR(INDEX(Programs!$B$6:$B$205,MATCH(B8,Programs!$A$6:$A$205,0)),""))} | H8: =IF(A8="","",IF(COUNTIFS(Deadlines!$D$6:$D$205,A8,Deadlines!$H$6:$H$205,"<>Completed",Deadlines!$G$6:$G$205,"<>")=0,"",MINIFS(Deadlines!$G$6:$G$205,Deadlines!$D$6:$D$205,A8,Deadlines!$H$6:$H$205,"<>Completed"))) | I8: =IF(H8="","",H8-TODAY()) | J8: =IF(A8="","",COUNTIFS(Tasks!$D$6:$D$205,A8,Tasks!$G$6:$G$205,"<>Done",Tasks!$H$6:$H$205,TRUE)+COUNTIFS(Documents!$K$6:$K$205,A8,Documents!$G$6:$G$205,"<>Ready")+COUNTIFS(Essays!$C$6:$C$205,A8,Essays!$G$6:$G$205,"<>Final")+COUNTIFS(Recommenders!$G$6:$G$205,A8,Recommenders!$H$6:$H$205,"<>Submitted"))
C9: {=IF(B9="","",IFERROR(INDEX(Programs!$C$6:$C$205,MATCH(B9,Programs!$A$6:$A$205,0)),""))} | D9: {=IF(B9="","",IFERROR(INDEX(Programs!$B$6:$B$205,MATCH(B9,Programs!$A$6:$A$205,0)),""))} | H9: =IF(A9="","",IF(COUNTIFS(Deadlines!$D$6:$D$205,A9,Deadlines!$H$6:$H$205,"<>Completed",Deadlines!$G$6:$G$205,"<>")=0,"",MINIFS(Deadlines!$G$6:$G$205,Deadlines!$D$6:$D$205,A9,Deadlines!$H$6:$H$205,"<>Completed"))) | I9: =IF(H9="","",H9-TODAY()) | J9: =IF(A9="","",COUNTIFS(Tasks!$D$6:$D$205,A9,Tasks!$G$6:$G$205,"<>Done",Tasks!$H$6:$H$205,TRUE)+COUNTIFS(Documents!$K$6:$K$205,A9,Documents!$G$6:$G$205,"<>Ready")+COUNTIFS(Essays!$C$6:$C$205,A9,Essays!$G$6:$G$205,"<>Final")+COUNTIFS(Recommenders!$G$6:$G$205,A9,Recommenders!$H$6:$H$205,"<>Submitted"))
C10: {=IF(B10="","",IFERROR(INDEX(Programs!$C$6:$C$205,MATCH(B10,Programs!$A$6:$A$205,0)),""))} | D10: {=IF(B10="","",IFERROR(INDEX(Programs!$B$6:$B$205,MATCH(B10,Programs!$A$6:$A$205,0)),""))} | H10: =IF(A10="","",IF(COUNTIFS(Deadlines!$D$6:$D$205,A10,Deadlines!$H$6:$H$205,"<>Completed",Deadlines!$G$6:$G$205,"<>")=0,"",MINIFS(Deadlines!$G$6:$G$205,Deadlines!$D$6:$D$205,A10,Deadlines!$H$6:$H$205,"<>Completed"))) | I10: =IF(H10="","",H10-TODAY()) | J10: =IF(A10="","",COUNTIFS(Tasks!$D$6:$D$205,A10,Tasks!$G$6:$G$205,"<>Done",Tasks!$H$6:$H$205,TRUE)+COUNTIFS(Documents!$K$6:$K$205,A10,Documents!$G$6:$G$205,"<>Ready")+COUNTIFS(Essays!$C$6:$C$205,A10,Essays!$G$6:$G$205,"<>Final")+COUNTIFS(Recommenders!$G$6:$G$205,A10,Recommenders!$H$6:$H$205,"<>Submitted"))
C11: {=IF(B11="","",IFERROR(INDEX(Programs!$C$6:$C$205,MATCH(B11,Programs!$A$6:$A$205,0)),""))} | D11: {=IF(B11="","",IFERROR(INDEX(Programs!$B$6:$B$205,MATCH(B11,Programs!$A$6:$A$205,0)),""))} | H11: =IF(A11="","",IF(COUNTIFS(Deadlines!$D$6:$D$205,A11,Deadlines!$H$6:$H$205,"<>Completed",Deadlines!$G$6:$G$205,"<>")=0,"",MINIFS(Deadlines!$G$6:$G$205,Deadlines!$D$6:$D$205,A11,Deadlines!$H$6:$H$205,"<>Completed"))) | I11: =IF(H11="","",H11-TODAY()) | J11: =IF(A11="","",COUNTIFS(Tasks!$D$6:$D$205,A11,Tasks!$G$6:$G$205,"<>Done",Tasks!$H$6:$H$205,TRUE)+COUNTIFS(Documents!$K$6:$K$205,A11,Documents!$G$6:$G$205,"<>Ready")+COUNTIFS(Essays!$C$6:$C$205,A11,Essays!$G$6:$G$205,"<>Final")+COUNTIFS(Recommenders!$G$6:$G$205,A11,Recommenders!$H$6:$H$205,"<>Submitted"))
C12: {=IF(B12="","",IFERROR(INDEX(Programs!$C$6:$C$205,MATCH(B12,Programs!$A$6:$A$205,0)),""))} | D12: {=IF(B12="","",IFERROR(INDEX(Programs!$B$6:$B$205,MATCH(B12,Programs!$A$6:$A$205,0)),""))} | H12: =IF(A12="","",IF(COUNTIFS(Deadlines!$D$6:$D$205,A12,Deadlines!$H$6:$H$205,"<>Completed",Deadlines!$G$6:$G$205,"<>")=0,"",MINIFS(Deadlines!$G$6:$G$205,Deadlines!$D$6:$D$205,A12,Deadlines!$H$6:$H$205,"<>Completed"))) | I12: =IF(H12="","",H12-TODAY()) | J12: =IF(A12="","",COUNTIFS(Tasks!$D$6:$D$205,A12,Tasks!$G$6:$G$205,"<>Done",Tasks!$H$6:$H$205,TRUE)+COUNTIFS(Documents!$K$6:$K$205,A12,Documents!$G$6:$G$205,"<>Ready")+COUNTIFS(Essays!$C$6:$C$205,A12,Essays!$G$6:$G$205,"<>Final")+COUNTIFS(Recommenders!$G$6:$G$205,A12,Recommenders!$H$6:$H$205,"<>Submitted"))
C13: {=IF(B13="","",IFERROR(INDEX(Programs!$C$6:$C$205,MATCH(B13,Programs!$A$6:$A$205,0)),""))} | D13: {=IF(B13="","",IFERROR(INDEX(Programs!$B$6:$B$205,MATCH(B13,Programs!$A$6:$A$205,0)),""))} | H13: =IF(A13="","",IF(COUNTIFS(Deadlines!$D$6:$D$205,A13,Deadlines!$H$6:$H$205,"<>Completed",Deadlines!$G$6:$G$205,"<>")=0,"",MINIFS(Deadlines!$G$6:$G$205,Deadlines!$D$6:$D$205,A13,Deadlines!$H$6:$H$205,"<>Completed"))) | I13: =IF(H13="","",H13-TODAY()) | J13: =IF(A13="","",COUNTIFS(Tasks!$D$6:$D$205,A13,Tasks!$G$6:$G$205,"<>Done",Tasks!$H$6:$H$205,TRUE)+COUNTIFS(Documents!$K$6:$K$205,A13,Documents!$G$6:$G$205,"<>Ready")+COUNTIFS(Essays!$C$6:$C$205,A13,Essays!$G$6:$G$205,"<>Final")+COUNTIFS(Recommenders!$G$6:$G$205,A13,Recommenders!$H$6:$H$205,"<>Submitted"))
C14: {=IF(B14="","",IFERROR(INDEX(Programs!$C$6:$C$205,MATCH(B14,Programs!$A$6:$A$205,0)),""))} | D14: {=IF(B14="","",IFERROR(INDEX(Programs!$B$6:$B$205,MATCH(B14,Programs!$A$6:$A$205,0)),""))} | H14: =IF(A14="","",IF(COUNTIFS(Deadlines!$D$6:$D$205,A14,Deadlines!$H$6:$H$205,"<>Completed",Deadlines!$G$6:$G$205,"<>")=0,"",MINIFS(Deadlines!$G$6:$G$205,Deadlines!$D$6:$D$205,A14,Deadlines!$H$6:$H$205,"<>Completed"))) | I14: =IF(H14="","",H14-TODAY()) | J14: =IF(A14="","",COUNTIFS(Tasks!$D$6:$D$205,A14,Tasks!$G$6:$G$205,"<>Done",Tasks!$H$6:$H$205,TRUE)+COUNTIFS(Documents!$K$6:$K$205,A14,Documents!$G$6:$G$205,"<>Ready")+COUNTIFS(Essays!$C$6:$C$205,A14,Essays!$G$6:$G$205,"<>Final")+COUNTIFS(Recommenders!$G$6:$G$205,A14,Recommenders!$H$6:$H$205,"<>Submitted"))
C15: {=IF(B15="","",IFERROR(INDEX(Programs!$C$6:$C$205,MATCH(B15,Programs!$A$6:$A$205,0)),""))} | D15: {=IF(B15="","",IFERROR(INDEX(Programs!$B$6:$B$205,MATCH(B15,Programs!$A$6:$A$205,0)),""))} | H15: =IF(A15="","",IF(COUNTIFS(Deadlines!$D$6:$D$205,A15,Deadlines!$H$6:$H$205,"<>Completed",Deadlines!$G$6:$G$205,"<>")=0,"",MINIFS(Deadlines!$G$6:$G$205,Deadlines!$D$6:$D$205,A15,Deadlines!$H$6:$H$205,"<>Completed"))) | I15: =IF(H15="","",H15-TODAY()) | J15: =IF(A15="","",COUNTIFS(Tasks!$D$6:$D$205,A15,Tasks!$G$6:$G$205,"<>Done",Tasks!$H$6:$H$205,TRUE)+COUNTIFS(Documents!$K$6:$K$205,A15,Documents!$G$6:$G$205,"<>Ready")+COUNTIFS(Essays!$C$6:$C$205,A15,Essays!$G$6:$G$205,"<>Final")+COUNTIFS(Recommenders!$G$6:$G$205,A15,Recommenders!$H$6:$H$205,"<>Submitted"))
C16: {=IF(B16="","",IFERROR(INDEX(Programs!$C$6:$C$205,MATCH(B16,Programs!$A$6:$A$205,0)),""))} | D16: {=IF(B16="","",IFERROR(INDEX(Programs!$B$6:$B$205,MATCH(B16,Programs!$A$6:$A$205,0)),""))} | H16: =IF(A16="","",IF(COUNTIFS(Deadlines!$D$6:$D$205,A16,Deadlines!$H$6:$H$205,"<>Completed",Deadlines!$G$6:$G$205,"<>")=0,"",MINIFS(Deadlines!$G$6:$G$205,Deadlines!$D$6:$D$205,A16,Deadlines!$H$6:$H$205,"<>Completed"))) | I16: =IF(H16="","",H16-TODAY()) | J16: =IF(A16="","",COUNTIFS(Tasks!$D$6:$D$205,A16,Tasks!$G$6:$G$205,"<>Done",Tasks!$H$6:$H$205,TRUE)+COUNTIFS(Documents!$K$6:$K$205,A16,Documents!$G$6:$G$205,"<>Ready")+COUNTIFS(Essays!$C$6:$C$205,A16,Essays!$G$6:$G$205,"<>Final")+COUNTIFS(Recommenders!$G$6:$G$205,A16,Recommenders!$H$6:$H$205,"<>Submitted"))
C17: {=IF(B17="","",IFERROR(INDEX(Programs!$C$6:$C$205,MATCH(B17,Programs!$A$6:$A$205,0)),""))} | D17: {=IF(B17="","",IFERROR(INDEX(Programs!$B$6:$B$205,MATCH(B17,Programs!$A$6:$A$205,0)),""))} | H17: =IF(A17="","",IF(COUNTIFS(Deadlines!$D$6:$D$205,A17,Deadlines!$H$6:$H$205,"<>Completed",Deadlines!$G$6:$G$205,"<>")=0,"",MINIFS(Deadlines!$G$6:$G$205,Deadlines!$D$6:$D$205,A17,Deadlines!$H$6:$H$205,"<>Completed"))) | I17: =IF(H17="","",H17-TODAY()) | J17: =IF(A17="","",COUNTIFS(Tasks!$D$6:$D$205,A17,Tasks!$G$6:$G$205,"<>Done",Tasks!$H$6:$H$205,TRUE)+COUNTIFS(Documents!$K$6:$K$205,A17,Documents!$G$6:$G$205,"<>Ready")+COUNTIFS(Essays!$C$6:$C$205,A17,Essays!$G$6:$G$205,"<>Final")+COUNTIFS(Recommenders!$G$6:$G$205,A17,Recommenders!$H$6:$H$205,"<>Submitted"))
C18: {=IF(B18="","",IFERROR(INDEX(Programs!$C$6:$C$205,MATCH(B18,Programs!$A$6:$A$205,0)),""))} | D18: {=IF(B18="","",IFERROR(INDEX(Programs!$B$6:$B$205,MATCH(B18,Programs!$A$6:$A$205,0)),""))} | H18: =IF(A18="","",IF(COUNTIFS(Deadlines!$D$6:$D$205,A18,Deadlines!$H$6:$H$205,"<>Completed",Deadlines!$G$6:$G$205,"<>")=0,"",MINIFS(Deadlines!$G$6:$G$205,Deadlines!$D$6:$D$205,A18,Deadlines!$H$6:$H$205,"<>Completed"))) | I18: =IF(H18="","",H18-TODAY()) | J18: =IF(A18="","",COUNTIFS(Tasks!$D$6:$D$205,A18,Tasks!$G$6:$G$205,"<>Done",Tasks!$H$6:$H$205,TRUE)+COUNTIFS(Documents!$K$6:$K$205,A18,Documents!$G$6:$G$205,"<>Ready")+COUNTIFS(Essays!$C$6:$C$205,A18,Essays!$G$6:$G$205,"<>Final")+COUNTIFS(Recommenders!$G$6:$G$205,A18,Recommenders!$H$6:$H$205,"<>Submitted"))
... C205: {=IF(B205="","",IFERROR(INDEX(Programs!$C$6:$C$205,MATCH(B205,Programs!$A$6:$A$205,0)),""))} | D205: {=IF(B205="","",IFERROR(INDEX(Programs!$B$6:$B$205,MATCH(B205,Programs!$A$6:$A$205,0)),""))} | H205: =IF(A205="","",IF(COUNTIFS(Deadlines!$D$6:$D$205,A205,Deadlines!$H$6:$H$205,"<>Completed",Deadlines!$G$6:$G$205,"<>")=0,"",MINIFS(Deadlines!$G$6:$G$205,Deadlines!$D$6:$D$205,A205,Deadlines!$H$6:$H$205,"<>Completed"))) | I205: =IF(H205="","",H205-TODAY()) | J205: =IF(A205="","",COUNTIFS(Tasks!$D$6:$D$205,A205,Tasks!$G$6:$G$205,"<>Done",Tasks!$H$6:$H$205,TRUE)+COUNTIFS(Documents!$K$6:$K$205,A205,Documents!$G$6:$G$205,"<>Ready")+COUNTIFS(Essays!$C$6:$C$205,A205,Essays!$G$6:$G$205,"<>Final")+COUNTIFS(Recommenders!$G$6:$G$205,A205,Recommenders!$H$6:$H$205,"<>Submitted"))

Sheet Deadlines
A1: Deadlines
A2: Record every important cutoff with its official source and a clear reminder plan.
A3: Tip: SAMPLE rows are instructional and ignored by Dashboard.
A5: Deadline ID | B5: Type | C5: Title | D5: Related ID | E5: Related Type | F5: Priority | G5: Due Date | H5: Status | I5: Days Left | J5: Source URL | K5: Last Verified | L5: Reminder Plan | M5: Notes | N5: Source URL | O5: Last Verified | P5: Reminder Plan | Q5: Notes
A6: SAMPLE-DL-001 | B6: Final | C6: Sample program application deadline | D6: SAMPLE-APP-001 | E6: Application | F6: 5 | G6: 46295 | H6: Active | I6: =IF(G6="","",G6-TODAY()) -> 39 | J6: https://example.edu/deadline | K6: 46256 | L6: 30, 14, 7, 3, 1 days before | M6: Replace this sample with a verified deadline.
I7: =IF(G7="","",G7-TODAY())
I8: =IF(G8="","",G8-TODAY())
I9: =IF(G9="","",G9-TODAY())
I10: =IF(G10="","",G10-TODAY())
I11: =IF(G11="","",G11-TODAY())
I12: =IF(G12="","",G12-TODAY())
I13: =IF(G13="","",G13-TODAY())
I14: =IF(G14="","",G14-TODAY())
I15: =IF(G15="","",G15-TODAY())
I16: =IF(G16="","",G16-TODAY())
I17: =IF(G17="","",G17-TODAY())
I18: =IF(G18="","",G18-TODAY())
... I205: =IF(G205="","",G205-TODAY())

Sheet Tasks
A1: Tasks
A2: Turn application requirements into concrete, prioritized work.
A3: Tip: SAMPLE rows are instructional and ignored by Dashboard.
A5: Task ID | B5: Task | C5: Related Type | D5: Related ID | E5: Priority | F5: Due Date | G5: Status | H5: Blocking? | I5: Days Left | J5: Notes | K5: Status | L5: Blocking? | M5: Days Left | N5: Notes
A6: SAMPLE-TASK-001 | B6: Request updated official transcript | C6: Application | D6: SAMPLE-APP-001 | E6: 5 | F6: 46264 | G6: To Do | H6: TRUE | I6: =IF(F6="","",F6-TODAY()) -> 8 | J6: Delete or replace this sample task.
H7: FALSE | I7: =IF(F7="","",F7-TODAY())
H8: FALSE | I8: =IF(F8="","",F8-TODAY())
H9: FALSE | I9: =IF(F9="","",F9-TODAY())
H10: FALSE | I10: =IF(F10="","",F10-TODAY())
H11: FALSE | I11: =IF(F11="","",F11-TODAY())
H12: FALSE | I12: =IF(F12="","",F12-TODAY())
H13: FALSE | I13: =IF(F13="","",F13-TODAY())
H14: FALSE | I14: =IF(F14="","",F14-TODAY())
H15: FALSE | I15: =IF(F15="","",F15-TODAY())
H16: FALSE | I16: =IF(F16="","",F16-TODAY())
H17: FALSE | I17: =IF(F17="","",F17-TODAY())
H18: FALSE | I18: =IF(F18="","",F18-TODAY())
... H205: FALSE | I205: =IF(F205="","",F205-TODAY())

Sheet Documents
A1: Documents
A2: Track exact document versions and link private Google Drive files—never public copies.
A3: Tip: SAMPLE rows are instructional and ignored by Dashboard.
A5: Document ID | B5: Document | C5: Category | D5: Version | E5: Drive File Link | F5: Expiry Date | G5: Status | H5: Current? | I5: Last Updated | J5: Related Type | K5: Related ID | L5: Notes | M5: Last Updated | N5: Related Type | O5: Related ID | P5: Notes
A6: SAMPLE-DOC-001 | B6: Curriculum Vitae | C6: CV | D6: v1 | G6: Needs Update | H6: TRUE | I6: 46256 | J6: Application | K6: SAMPLE-APP-001 | L6: Add a private Drive file link, then replace this sample.
H7: FALSE
H8: FALSE
H9: FALSE
H10: FALSE
H11: FALSE
H12: FALSE
H13: FALSE
H14: FALSE
H15: FALSE
H16: FALSE
H17: FALSE
H18: FALSE
... H205: FALSE

Sheet Essays
A1: Essays
A2: Track prompts, limits, versions, reviews and final draft links.
A3: Tip: SAMPLE rows are instructional and ignored by Dashboard.
A5: Essay ID | B5: Essay / Prompt | C5: Application ID | D5: Type | E5: Word Limit | F5: Word Count | G5: Status | H5: Due Date | I5: Current Version | J5: Draft Link | K5: Reviewer | L5: Notes | M5: Current Version | N5: Draft Link | O5: Reviewer | P5: Notes
A6: SAMPLE-ESS-001 | B6: Statement of purpose | C6: SAMPLE-APP-001 | D6: Statement of Purpose | E6: 1000 | F6: 0 | G6: Not Started | H6: 46285 | I6: v0 | L6: Replace this sample with the exact official prompt.

Sheet Recommenders
A1: Recommenders
A2: Track every recommendation request, workload, follow-up and submission date.
A3: Tip: SAMPLE rows are instructional and ignored by Dashboard.
A5: Recommender ID | B5: Name | C5: Title / Institution | D5: Email | E5: Relationship | F5: Request ID | G5: Application ID | H5: Status | I5: Requested | J5: Due Date | K5: Submitted | L5: Follow-up | M5: Notes | N5: Due Date | O5: Submitted | P5: Follow-up | Q5: Notes
A6: SAMPLE-REC-001 | B6: Sample Recommender | C6: Professor · Sample University | D6: sample@example.edu | E6: Course instructor | F6: SAMPLE-REQ-001 | G6: SAMPLE-APP-001 | H6: Planned | J6: 46280 | L6: 46266 | M6: Delete or replace this sample row.

Sheet Contacts
A1: Contacts
A2: Keep professor, admissions, alumni and scholarship conversations organized.
A3: Tip: SAMPLE rows are instructional and ignored by Dashboard.
A5: Contact ID | B5: Name | C5: Type | D5: Institution | E5: Program | F5: Email | G5: Profile URL | H5: Last Contacted | I5: Next Follow-up | J5: Notes | K5: Profile URL | L5: Last Contacted | M5: Next Follow-up | N5: Notes
A6: SAMPLE-CON-001 | B6: Sample Professor | C6: Professor | D6: Sample University | E6: MSc Artificial Intelligence | F6: sample@example.edu | I6: 46270 | J6: Delete or replace this sample contact.

Sheet Costs
A1: Costs
A2: Track exact costs by currency without guessed exchange rates.
A3: Tip: SAMPLE rows are instructional and ignored by Dashboard.
A5: Cost ID | B5: Related Type | C5: Related ID | D5: Category | E5: Description | F5: Amount | G5: Currency | H5: Status | I5: Due Date | J5: Paid Date | K5: Notes | L5: Amount (GHS) | M5: Amount (EUR) | N5: Amount (USD) | O5: Notes
A6: SAMPLE-COST-001 | B6: Application | C6: SAMPLE-APP-001 | D6: Application Fee | E6: Sample application fee | F6: 100 | G6: EUR | H6: Due | I6: 46290 | K6: Delete or replace this sample cost. | L6: =IF(OR(F6="",G6=""),"",IFERROR(F6*VLOOKUP(G6,Setup!$A$38:$E$52,5,FALSE),"")) -> 1301.8 | M6: =IF(L6="","",IFERROR(L6/VLOOKUP("EUR",Setup!$A$38:$E$52,5,FALSE),"")) -> 100 | N6: =IF(L6="","",IFERROR(L6/VLOOKUP("USD",Setup!$A$38:$E$52,5,FALSE),"")) -> 116.88503
L7: =IF(OR(F7="",G7=""),"",IFERROR(F7*VLOOKUP(G7,Setup!$A$38:$E$52,5,FALSE),"")) | M7: =IF(L7="","",IFERROR(L7/VLOOKUP("EUR",Setup!$A$38:$E$52,5,FALSE),"")) | N7: =IF(L7="","",IFERROR(L7/VLOOKUP("USD",Setup!$A$38:$E$52,5,FALSE),""))
L8: =IF(OR(F8="",G8=""),"",IFERROR(F8*VLOOKUP(G8,Setup!$A$38:$E$52,5,FALSE),"")) | M8: =IF(L8="","",IFERROR(L8/VLOOKUP("EUR",Setup!$A$38:$E$52,5,FALSE),"")) | N8: =IF(L8="","",IFERROR(L8/VLOOKUP("USD",Setup!$A$38:$E$52,5,FALSE),""))
L9: =IF(OR(F9="",G9=""),"",IFERROR(F9*VLOOKUP(G9,Setup!$A$38:$E$52,5,FALSE),"")) | M9: =IF(L9="","",IFERROR(L9/VLOOKUP("EUR",Setup!$A$38:$E$52,5,FALSE),"")) | N9: =IF(L9="","",IFERROR(L9/VLOOKUP("USD",Setup!$A$38:$E$52,5,FALSE),""))
L10: =IF(OR(F10="",G10=""),"",IFERROR(F10*VLOOKUP(G10,Setup!$A$38:$E$52,5,FALSE),"")) | M10: =IF(L10="","",IFERROR(L10/VLOOKUP("EUR",Setup!$A$38:$E$52,5,FALSE),"")) | N10: =IF(L10="","",IFERROR(L10/VLOOKUP("USD",Setup!$A$38:$E$52,5,FALSE),""))
L11: =IF(OR(F11="",G11=""),"",IFERROR(F11*VLOOKUP(G11,Setup!$A$38:$E$52,5,FALSE),"")) | M11: =IF(L11="","",IFERROR(L11/VLOOKUP("EUR",Setup!$A$38:$E$52,5,FALSE),"")) | N11: =IF(L11="","",IFERROR(L11/VLOOKUP("USD",Setup!$A$38:$E$52,5,FALSE),""))
L12: =IF(OR(F12="",G12=""),"",IFERROR(F12*VLOOKUP(G12,Setup!$A$38:$E$52,5,FALSE),"")) | M12: =IF(L12="","",IFERROR(L12/VLOOKUP("EUR",Setup!$A$38:$E$52,5,FALSE),"")) | N12: =IF(L12="","",IFERROR(L12/VLOOKUP("USD",Setup!$A$38:$E$52,5,FALSE),""))
L13: =IF(OR(F13="",G13=""),"",IFERROR(F13*VLOOKUP(G13,Setup!$A$38:$E$52,5,FALSE),"")) | M13: =IF(L13="","",IFERROR(L13/VLOOKUP("EUR",Setup!$A$38:$E$52,5,FALSE),"")) | N13: =IF(L13="","",IFERROR(L13/VLOOKUP("USD",Setup!$A$38:$E$52,5,FALSE),""))
L14: =IF(OR(F14="",G14=""),"",IFERROR(F14*VLOOKUP(G14,Setup!$A$38:$E$52,5,FALSE),"")) | M14: =IF(L14="","",IFERROR(L14/VLOOKUP("EUR",Setup!$A$38:$E$52,5,FALSE),"")) | N14: =IF(L14="","",IFERROR(L14/VLOOKUP("USD",Setup!$A$38:$E$52,5,FALSE),""))
L15: =IF(OR(F15="",G15=""),"",IFERROR(F15*VLOOKUP(G15,Setup!$A$38:$E$52,5,FALSE),"")) | M15: =IF(L15="","",IFERROR(L15/VLOOKUP("EUR",Setup!$A$38:$E$52,5,FALSE),"")) | N15: =IF(L15="","",IFERROR(L15/VLOOKUP("USD",Setup!$A$38:$E$52,5,FALSE),""))
L16: =IF(OR(F16="",G16=""),"",IFERROR(F16*VLOOKUP(G16,Setup!$A$38:$E$52,5,FALSE),"")) | M16: =IF(L16="","",IFERROR(L16/VLOOKUP("EUR",Setup!$A$38:$E$52,5,FALSE),"")) | N16: =IF(L16="","",IFERROR(L16/VLOOKUP("USD",Setup!$A$38:$E$52,5,FALSE),""))
L17: =IF(OR(F17="",G17=""),"",IFERROR(F17*VLOOKUP(G17,Setup!$A$38:$E$52,5,FALSE),"")) | M17: =IF(L17="","",IFERROR(L17/VLOOKUP("EUR",Setup!$A$38:$E$52,5,FALSE),"")) | N17: =IF(L17="","",IFERROR(L17/VLOOKUP("USD",Setup!$A$38:$E$52,5,FALSE),""))
L18: =IF(OR(F18="",G18=""),"",IFERROR(F18*VLOOKUP(G18,Setup!$A$38:$E$52,5,FALSE),"")) | M18: =IF(L18="","",IFERROR(L18/VLOOKUP("EUR",Setup!$A$38:$E$52,5,FALSE),"")) | N18: =IF(L18="","",IFERROR(L18/VLOOKUP("USD",Setup!$A$38:$E$52,5,FALSE),""))
... L205: =IF(OR(F205="",G205=""),"",IFERROR(F205*VLOOKUP(G205,Setup!$A$38:$E$52,5,FALSE),"")) | M205: =IF(L205="","",IFERROR(L205/VLOOKUP("EUR",Setup!$A$38:$E$52,5,FALSE),"")) | N205: =IF(L205="","",IFERROR(L205/VLOOKUP("USD",Setup!$A$38:$E$52,5,FALSE),""))

Sheet Decisions
A1: Decisions
A2: Compare offers, funding conditions, response deadlines and final choices.
A3: Tip: SAMPLE rows are instructional and ignored by Dashboard.
A5: Decision ID | B5: Application ID | C5: Program | D5: Admission Status | E5: Scholarship Status | F5: Funding Amount | G5: Currency | H5: Conditions | I5: Response Deadline | J5: Deposit | K5: Deposit Currency | L5: Final Choice? | M5: Notes | N5: Funding (GHS) | O5: Funding (EUR) | P5: Funding (USD) | Q5: Deposit (GHS) | R5: Deposit (EUR) | S5: Deposit (USD)
